Workbook

Sheet LEEME
A1: Sistema integrado de control de la UGP — LÉEME
A2: DATOS SIMULADOS con fines de demostración metodológica — no son cifras reales del BID ni de la Dirección de Integración.
A4: Qué es
A5: Libro de control de ejecución para la Unidad Gestora del Programa (UGP) del Programa de Integración Académica y Comunitaria para Jóvenes en El Salvador (operaciones BID ES-L1175 / ES-J0003; Contrato de Préstamo 6153/OC-ES por US$100 M y Convenio no reembolsable 6154/GR-ES por US$4 M). Organiza el ciclo del TDR en cuatro pilares: planificación y control integral, gestión fiduciaria, cumplimiento normativo y articulación y reporte.
A6: ADVERTENCIA: todos los datos son SIMULADOS y la estructura de componentes es ILUSTRATIVA. Se tomaron del TDR solo los montos, números de operación y condiciones de la consultoría. Antes de usarlo con datos reales hay que contrastarlo con el Contrato de Préstamo, el MOP, el PEP, el Plan de Adquisiciones y los sistemas del BID.
A8: Código de colores
A9: Texto azul = dato que se ingresa o edita
A10: Texto negro sobre gris = fórmula (no editar)
A11: Semáforo verde / amarillo / rojo = según los umbrales de la hoja Parametros
A13: Ciclo de cierre mensual (informe a más tardar 3 días hábiles tras el cierre)
A14: 1. Registrar los gastos del mes en F2_Ejecucion y los desembolsos en F3_Desembolsos.
A15: 2. Actualizar % de avance físico en P1_POA, valores actuales en P1_Resultados y estados en F4/F5.
... A21: Índice de hojas
A22: Hoja | B22: Pilar | C22: Qué hace | D22: Mantiene | E22: Frecuencia
A23: Tablero | B23: Base | C23: Semáforos ejecutivos, mapa de calor de riesgos y gráficos | D23: Esp. Planificación | E23: Mensual
A24: Parametros | B24: Base | C24: Datos del TDR, fecha de corte, umbrales y pesos | D24: Coordinador General | E24: Mensual (fecha de corte)
A25: Controles | B25: Base | C25: 16 pruebas automáticas de consistencia entre hojas | D25: Esp. Planificación | E25: Mensual, antes del informe
A26: P1_Resultados | B26: 1 Planificación y control | C26: Matriz de resultados: metas anuales, esperado al corte, cumplimiento y semáforo | D26: Esp. Planificación | E26: Mensual / anual
A27: P1_POA | B27: 1 Planificación y control | C27: POA e hitos con valor ganado (EV, PV, AC, SPI, CPI) por actividad | D27: Esp. Planificación | E27: Mensual
A28: P1_Avance_FF | B28: 1 Planificación y control | C28: Avance físico y financiero consolidado por componente | D28: Esp. Planificación | E28: Mensual
A29: P1_Riesgos | B29: 1 Planificación y control | C29: Registro de riesgos, puntaje P×I, respuesta y riesgo residual | D29: Esp. Planificación | E29: Mensual
A30: P2_Focalizacion | B30: 1 Planificación y control | C30: Metas, cobertura, índice de focalización e inversión por departamento | D30: Esp. Social | E30: Mensual
A31: F1_Presupuesto_PEP | B31: 2 Gestión fiduciaria | C31: Presupuesto por componente y fuente, PEP a 5 años y ejecución | D31: Esp. Financiero | E31: Trimestral
A32: F2_Ejecucion | B32: 2 Gestión fiduciaria | C32: Libro de gastos: fuente única de la ejecución | D32: Esp. Financiero | E32: Continua
A33: F3_Desembolsos | B33: 2 Gestión fiduciaria | C33: Solicitudes de desembolso y control del anticipo (umbral de justificación) | D33: Esp. Financiero | E33: Quincenal / mensual
... A46: Listas | B46: Base | C46: Listas desplegables | D46: Esp. Planificación | E46: Cuando cambie

Sheet Tablero
A1: Tablero de control de la UGP — Programa de Integración Académica y Comunitaria para Jóvenes
A2: DATOS SIMULADOS con fines de demostración metodológica — no son cifras reales del BID ni de la Dirección de Integración.
A3: Fecha de corte: | B3: =Fecha_Corte -> 46568 | C3: =Estado_Controles -> TODOS LOS CONTROLES OK
A5: Indicador clave | B5: Valor | C5: Referencia | D5: Semáforo
A6: Presupuesto total del Programa (USD) | B6: =Total_Programa -> 104000000
A7: Ejecutado acumulado (USD) | B7: =F1_Presupuesto_PEP!N10 -> 2728350
A8: % ejecutado sobre el total del Programa | B8: =F1_Presupuesto_PEP!O10 -> 0.026234135
A9: Avance físico del POA (real vs. planificado a la fecha) | B9: =P1_Avance_FF!F10 -> 0.44792308 | C9: =P1_Avance_FF!G10 -> 0.52567146 | D9: =IF(B9/C9>=Umbral_Verde,"Verde",IF(B9/C9>=Umbral_Amarillo,"Amarillo","Rojo")) -> Amarillo
A10: Avance financiero del POA (ejecutado / presupuesto POA) | B10: =P1_Avance_FF!E10 -> 0.41974615 | C10: =P1_Avance_FF!G10 -> 0.52567146
A11: SPI — índice de desempeño del cronograma | B11: =P1_Avance_FF!J10 -> 0.852097 | C11: 1 | D11: =IF(B11>=EVM_Verde,"Verde",IF(B11>=EVM_Amarillo,"Amarillo","Rojo")) -> Amarillo
A12: CPI — índice de desempeño del costo | B12: =P1_Avance_FF!K10 -> 1.0671285 | C12: 1 | D12: =IF(B12>=EVM_Verde,"Verde",IF(B12>=EVM_Amarillo,"Amarillo","Rojo")) -> Verde
A13: Total desembolsado por el BID (USD) | B13: =F3_Desembolsos!L13 -> 2996450
A14: % de anticipos justificado | B14: =F3_Desembolsos!L8 -> 0.69822917 | C14: =Pct_Justif_Min -> 0.8 | D14: =IF(B14>=C14,"Verde",IF(B14>=C14-0.1,"Amarillo","Rojo")) -> Rojo
A15: Procesos de adquisición atrasados | B15: =COUNTIF(F4_Plan_Adquisiciones!$P$5:$P$200,"Atrasado") -> 1 | C15: 0 | D15: =IF(B15=0,"Verde",IF(B15<=2,"Amarillo","Rojo")) -> Amarillo
A16: No Objeciones pendientes fuera del plazo de referencia | B16: =COUNTIF(A3_No_Objeciones!$I$5:$I$200,"Pendiente fuera de referencia") -> 1 | C16: 0 | D16: =IF(B16=0,"Verde",IF(B16<=2,"Amarillo","Rojo")) -> Amarillo
A17: Compromisos con el BID vencidos | B17: =COUNTIFS(A2_Misiones_BID!$E$14:$E$100,"<"&Fecha_Corte,A2_Misiones_BID!$G$14:$G$100,"<>Cumplido",A2_Misiones_BID!$A$14:$A$100,"CM-*") -> 2 | C17: 0 | D17: =IF(B17=0,"Verde",IF(B17<=2,"Amarillo","Rojo")) -> Amarillo
A18: Riesgos altos abiertos | B18: =COUNTIFS(P1_Riesgos!$H$5:$H$200,"Alto",P1_Riesgos!$M$5:$M$200,"<>Cerrado") -> 3 | C18: 0 | D18: =IF(B18=0,"Verde",IF(B18<=2,"Amarillo","Rojo")) -> Rojo
A19: Obligaciones normativas vencidas | B19: =N1_Cumplimiento!O8 -> 1 | C19: 0 | D19: =IF(B19=0,"Verde",IF(B19<=2,"Amarillo","Rojo")) -> Amarillo
A20: % de cumplimiento de obligaciones exigibles | B20: =N1_Cumplimiento!O10 -> 0.88888889 | C20: 1 | D20: =IF(B20>=Umbral_Verde,"Verde",IF(B20>=Umbral_Amarillo,"Amarillo","Rojo")) -> Amarillo
A21: Cobertura de la meta de beneficiarios del año 1 (vs. fracción del año) | B21: =P2_Focalizacion!K19 -> 0.39666667 | C21: =Frac_Anio -> 0.49281314 | D21: =IF(B21/C21>=Umbral_Verde,"Verde",IF(B21/C21>=Umbral_Amarillo,"Amarillo","Rojo")) -> Amarillo
A24: Mapa de calor de riesgos abiertos (n.º de riesgos por probabilidad × impacto)
A25: Impacto ↓ / Probabilidad → | B25: 1 | C25: 2 | D25: 3 | E25: 4 | F25: 5
A26: 5 | B26: =COUNTIFS(P1_Riesgos!$E$5:$E$200,B$25,P1_Riesgos!$F$5:$F$200,$A26,P1_Riesgos!$M$5:$M$200,"<>Cerrado") -> 0 | C26: =COUNTIFS(P1_Riesgos!$E$5:$E$200,C$25,P1_Riesgos!$F$5:$F$200,$A26,P1_Riesgos!$M$5:$M$200,"<>Cerrado") -> 1 | D26: =COUNTIFS(P1_Riesgos!$E$5:$E$200,D$25,P1_Riesgos!$F$5:$F$200,$A26,P1_Riesgos!$M$5:$M$200,"<>Cerrado") -> 1 | E26: =COUNTIFS(P1_Riesgos!$E$5:$E$200,E$25,P1_Riesgos!$F$5:$F$200,$A26,P1_Riesgos!$M$5:$M$200,"<>Cerrado") -> 0 | F26: =COUNTIFS(P1_Riesgos!$E$5:$E$200,F$25,P1_Riesgos!$F$5:$F$200,$A26,P1_Riesgos!$M$5:$M$200,"<>Cerrado") -> 0
A27: 4 | B27: =COUNTIFS(P1_Riesgos!$E$5:$E$200,B$25,P1_Riesgos!$F$5:$F$200,$A27,P1_Riesgos!$M$5:$M$200,"<>Cerrado") -> 1 | C27: =COUNTIFS(P1_Riesgos!$E$5:$E$200,C$25,P1_Riesgos!$F$5:$F$200,$A27,P1_Riesgos!$M$5:$M$200,"<>Cerrado") -> 2 | D27: =COUNTIFS(P1_Riesgos!$E$5:$E$200,D$25,P1_Riesgos!$F$5:$F$200,$A27,P1_Riesgos!$M$5:$M$200,"<>Cerrado") -> 5 | E27: =COUNTIFS(P1_Riesgos!$E$5:$E$200,E$25,P1_Riesgos!$F$5:$F$200,$A27,P1_Riesgos!$M$5:$M$200,"<>Cerrado") -> 2 | F27: =COUNTIFS(P1_Riesgos!$E$5:$E$200,F$25,P1_Riesgos!$F$5:$F$200,$A27,P1_Riesgos!$M$5:$M$200,"<>Cerrado") -> 0
A28: 3 | B28: =COUNTIFS(P1_Riesgos!$E$5:$E$200,B$25,P1_Riesgos!$F$5:$F$200,$A28,P1_Riesgos!$M$5:$M$200,"<>Cerrado") -> 0 | C28: =COUNTIFS(P1_Riesgos!$E$5:$E$200,C$25,P1_Riesgos!$F$5:$F$200,$A28,P1_Riesgos!$M$5:$M$200,"<>Cerrado") -> 0 | D28: =COUNTIFS(P1_Riesgos!$E$5:$E$200,D$25,P1_Riesgos!$F$5:$F$200,$A28,P1_Riesgos!$M$5:$M$200,"<>Cerrado") -> 2 | E28: =COUNTIFS(P1_Riesgos!$E$5:$E$200,E$25,P1_Riesgos!$F$5:$F$200,$A28,P1_Riesgos!$M$5:$M$200,"<>Cerrado") -> 1 | F28: =COUNTIFS(P1_Riesgos!$E$5:$E$200,F$25,P1_Riesgos!$F$5:$F$200,$A28,P1_Riesgos!$M$5:$M$200,"<>Cerrado") -> 0
A29: 2 | B29: =COUNTIFS(P1_Riesgos!$E$5:$E$200,B$25,P1_Riesgos!$F$5:$F$200,$A29,P1_Riesgos!$M$5:$M$200,"<>Cerrado") -> 0 | C29: =COUNTIFS(P1_Riesgos!$E$5:$E$200,C$25,P1_Riesgos!$F$5:$F$200,$A29,P1_Riesgos!$M$5:$M$200,"<>Cerrado") -> 0 | D29: =COUNTIFS(P1_Riesgos!$E$5:$E$200,D$25,P1_Riesgos!$F$5:$F$200,$A29,P1_Riesgos!$M$5:$M$200,"<>Cerrado") -> 0 | E29: =COUNTIFS(P1_Riesgos!$E$5:$E$200,E$25,P1_Riesgos!$F$5:$F$200,$A29,P1_Riesgos!$M$5:$M$200,"<>Cerrado") -> 0 | F29: =COUNTIFS(P1_Riesgos!$E$5:$E$200,F$25,P1_Riesgos!$F$5:$F$200,$A29,P1_Riesgos!$M$5:$M$200,"<>Cerrado") -> 0
A30: 1 | B30: =COUNTIFS(P1_Riesgos!$E$5:$E$200,B$25,P1_Riesgos!$F$5:$F$200,$A30,P1_Riesgos!$M$5:$M$200,"<>Cerrado") -> 0 | C30: =COUNTIFS(P1_Riesgos!$E$5:$E$200,C$25,P1_Riesgos!$F$5:$F$200,$A30,P1_Riesgos!$M$5:$M$200,"<>Cerrado") -> 0 | D30: =COUNTIFS(P1_Riesgos!$E$5:$E$200,D$25,P1_Riesgos!$F$5:$F$200,$A30,P1_Riesgos!$M$5:$M$200,"<>Cerrado") -> 0 | E30: =COUNTIFS(P1_Riesgos!$E$5:$E$200,E$25,P1_Riesgos!$F$5:$F$200,$A30,P1_Riesgos!$M$5:$M$200,"<>Cerrado") -> 0 | F30: =COUNTIFS(P1_Riesgos!$E$5:$E$200,F$25,P1_Riesgos!$F$5:$F$200,$A30,P1_Riesgos!$M$5:$M$200,"<>Cerrado") -> 0

Sheet Parametros
A1: Parámetros del Programa y del sistema de control
A2: DATOS SIMULADOS con fines de demostración metodológica — no son cifras reales del BID ni de la Dirección de Integración.
A3: Celdas azules = entradas editables. Las celdas con nombre (p. ej. Fecha_Corte) alimentan todas las hojas.
A4: Grupo | B4: Parámetro | C4: Valor | D4: Unidad | E4: Nombre en fórmulas | F4: Fuente / nota
A5: Programa | B5: Programa | C5: Programa de Integración Académica y Comunitaria para Jóvenes en El Salvador | F5: TDR, carátula
A6: Programa | B6: Operaciones BID | C6: ES-L1175 y ES-J0003 | F6: TDR; CCLIP ES-O0023
A7: Programa | B7: Contrato de Préstamo | C7: 6153/OC-ES | F7: TDR (el texto del usuario decía «6153 OCS»; el TDR dice 6153/OC-ES)
A8: Programa | B8: Convenio de Financiamiento No Reembolsable | C8: 6154/GR-ES | F8: TDR
A9: Programa | B9: Resolución de aprobación BID | C9: DE-43/26 (24-jun-2026) | F9: TDR §I
A10: Programa | B10: Organismo Ejecutor | C10: Dirección de Integración | F10: TDR; la UGP está adscrita a la Gerencia de Cooperación Institucional
A11: Programa | B11: Monto del préstamo | C11: 100000000 | D11: USD | E11: Total_Prestamo | F11: TDR §I
A12: Programa | B12: Monto de la donación | C12: 4000000 | D12: USD | E12: Total_Donacion | F12: TDR §I
A13: Programa | B13: Total financiamiento BID | C13: =C11+C12 -> 104000000 | D13: USD | E13: Total_Programa | F13: Calculado
A14: Programa | B14: Duración | C14: 5 | D14: años | E14: Duracion_Anios | F14: TDR §I
A15: Calendario | B15: Fecha de inicio de ejecución (SUPUESTO) | C15: 46388 | D15: fecha | E15: Fecha_Inicio | F15: Supuesto de la demo: la fecha real depende de la entrada en vigencia
A16: Calendario | B16: Fecha de corte del reporte (SIMULADA) | C16: 46568 | D16: fecha | E16: Fecha_Corte | F16: Cambie esta fecha y todo el sistema se recalcula
A17: Calendario | B17: Año del programa a la fecha de corte | C17: =INT((Fecha_Corte-Fecha_Inicio)/365.25)+1 -> 1 | D17: año | E17: Anio_Programa | F17: Calculado
A18: Calendario | B18: Fracción transcurrida del año del programa | C18: =(Fecha_Corte-Fecha_Inicio)/365.25-(Anio_Programa-1) -> 0.49281314 | D18: % | E18: Frac_Anio | F18: Calculado
A19: Calendario | B19: Inicio de la consultoría del Coordinador General (SUPUESTO) | C19: 46391 | D19: fecha | E19: Inicio_Consultoria | F19: Supuesto: plazo de 12 meses desde la firma (TDR §VIII)
A20: Consultoría | B20: Honorario mensual del Coordinador General | C20: 4200 | D20: USD | E20: Pago_Mensual | F20: TDR §XII (US$50,400 en 12 pagos)
A21: Consultoría | B21: Plazo de entrega del informe mensual | C21: 3 | D21: días hábiles | E21: Plazo_Informe | F21: TDR §VII: tres días hábiles posteriores al cierre del mes
A22: Semáforos | B22: Indicadores: umbral verde (cumplimiento ≥) | C22: 0.9 | D22: ratio | E22: Umbral_Verde | F22: Criterio de gestión propuesto
A23: Semáforos | B23: Indicadores: umbral amarillo (cumplimiento ≥) | C23: 0.7 | D23: ratio | E23: Umbral_Amarillo | F23: Criterio de gestión propuesto
A24: Semáforos | B24: SPI/CPI: umbral verde (≥) | C24: 0.95 | D24: ratio | E24: EVM_Verde | F24: Criterio de gestión propuesto
A25: Semáforos | B25: SPI/CPI: umbral amarillo (≥) | C25: 0.85 | D25: ratio | E25: EVM_Amarillo | F25: Criterio de gestión propuesto
A26: Semáforos | B26: Riesgo ALTO si probabilidad×impacto ≥ | C26: 15 | D26: puntos | E26: Riesgo_Alto | F26: Escala 1-5 × 1-5
A27: Semáforos | B27: Riesgo MEDIO si probabilidad×impacto ≥ | C27: 8 | D27: puntos | E27: Riesgo_Medio | F27: Escala 1-5 × 1-5
A28: Semáforos | B28: Alerta de vencimiento (días antes) | C28: 30 | D28: días | E28: Dias_Alerta | F28: Criterio de gestión propuesto
A29: Fiduciario | B29: Justificación mínima de anticipos para pedir uno nuevo | C29: 0.8 | D29: % | E29: Pct_Justif_Min | F29: A VALIDAR con el Contrato de Préstamo / guía de gestión financiera del BID
A30: Fiduciario | B30: Plazo de referencia de trámite de No Objeción | C30: 15 | D30: días | E30: Plazo_NO | F30: Referencia INTERNA de la UGP, no un plazo del BID
... A38: Focalización | B38: Meta de beneficiarios a 5 años (SIMULADA) | C38: 60000 | D38: personas | E38: Meta_Benef_5A | F38: Dato sintético

Sheet Controles
A1: Controles de integridad del sistema
A2: DATOS SIMULADOS con fines de demostración metodológica — no son cifras reales del BID ni de la Dirección de Integración.
A3: Pruebas automáticas de consistencia entre hojas. Cualquier «REVISAR» debe corregirse antes de emitir el informe mensual.
A4: N.º | B4: Control | C4: Esperado | D4: Calculado | E4: Diferencia | F4: Estado
A5: 1 | B5: Presupuesto por componentes = total del Programa (USD) | C5: =Total_Programa -> 104000000 | D5: =F1_Presupuesto_PEP!E10 -> 104000000 | E5: =D5-C5 -> 0 | F5: =IF(ROUND(E5,0)=0,"OK","REVISAR") -> OK
A6: 2 | B6: Total préstamo asignado = monto del Contrato 6153/OC-ES | C6: =Total_Prestamo -> 100000000 | D6: =F1_Presupuesto_PEP!C10 -> 100000000 | E6: =D6-C6 -> 0 | F6: =IF(ROUND(E6,0)=0,"OK","REVISAR") -> OK
A7: 3 | B7: Total donación asignada = monto del Convenio 6154/GR-ES | C7: =Total_Donacion -> 4000000 | D7: =F1_Presupuesto_PEP!D10 -> 4000000 | E7: =D7-C7 -> 0 | F7: =IF(ROUND(E7,0)=0,"OK","REVISAR") -> OK
A8: 4 | B8: Componentes cuyo PEP a 5 años no coincide con lo asignado | C8: 0 | D8: =COUNTIF(F1_Presupuesto_PEP!M5:M9,"REVISAR") -> 0 | E8: =D8-C8 -> 0 | F8: =IF(ROUND(E8,0)=0,"OK","REVISAR") -> OK
A9: 5 | B9: Plan financiero del año 1 = presupuesto POA (USD) | C9: =P1_Avance_FF!C10 -> 6500000 | D9: =SUM(F3_Plan_Financiero!D5:D8) -> 6500000 | E9: =D9-C9 -> 0 | F9: =IF(ROUND(E9,0)=0,"OK","REVISAR") -> OK
A10: 6 | B10: Ejecución acumulada ≤ presupuesto total (USD) | C10: =F1_Presupuesto_PEP!E10 -> 104000000 | D10: =F1_Presupuesto_PEP!N10 -> 2728350 | E10: =D10-C10 -> -101271650 | F10: =IF(D10<=C10,"OK","REVISAR") -> OK
A11: 7 | B11: Actividades POA con ejecutado > presupuesto | C11: 0 | D11: =SUMPRODUCT(--(P1_POA!$J$5:$J$200>P1_POA!$G$5:$G$200)) -> 0 | E11: =D11-C11 -> 0 | F11: =IF(ROUND(E11,0)=0,"OK","REVISAR") -> OK
A12: 8 | B12: Contratos con pagos > monto contratado | C12: 0 | D12: =SUM(F5_Contratos!$P$5:$P$200) -> 0 | E12: =D12-C12 -> 0 | F12: =IF(ROUND(E12,0)=0,"OK","REVISAR") -> OK
A13: 9 | B13: Gastos cuyo componente no coincide con el de su actividad | C13: 0 | D13: =SUM(F2_Ejecucion!$N$5:$N$500) -> 0 | E13: =D13-C13 -> 0 | F13: =IF(ROUND(E13,0)=0,"OK","REVISAR") -> OK
A14: 10 | B14: Gastos fuera del período [inicio, corte] | C14: 0 | D14: =COUNTIFS(F2_Ejecucion!$B$5:$B$500,"<"&Fecha_Inicio)+COUNTIFS(F2_Ejecucion!$B$5:$B$500,">"&Fecha_Corte) -> 0 | E14: =D14-C14 -> 0 | F14: =IF(ROUND(E14,0)=0,"OK","REVISAR") -> OK
A15: 11 | B15: Gastos con contrato inexistente en F5 | C15: 0 | D15: =SUMPRODUCT((F2_Ejecucion!$E$5:$E$500<>"")*(COUNTIF(F5_Contratos!$A$5:$A$200,F2_Ejecucion!$E$5:$E$500)=0)) -> 0 | E15: =D15-C15 -> 0 | F15: =IF(ROUND(E15,0)=0,"OK","REVISAR") -> OK
A16: 12 | B16: Gastos con actividad inexistente en el POA | C16: 0 | D16: =SUMPRODUCT((F2_Ejecucion!$D$5:$D$500<>"")*(COUNTIF(P1_POA!$A$5:$A$200,F2_Ejecucion!$D$5:$D$500)=0)) -> 0 | E16: =D16-C16 -> 0 | F16: =IF(ROUND(E16,0)=0,"OK","REVISAR") -> OK
A17: 13 | B17: Pagos directos del libro = desembolsos por pago directo (USD) | C17: =F3_Desembolsos!L12 -> 596450 | D17: =F3_Desembolsos!L11 -> 596450 | E17: =D17-C17 -> 0 | F17: =IF(ROUND(E17,0)=0,"OK","REVISAR") -> OK
A18: 14 | B18: Meta nacional de beneficiarios = suma de departamentos | C18: =Meta_Benef_5A -> 60000 | D18: =P2_Focalizacion!E19 -> 60000 | E18: =D18-C18 -> 0 | F18: =IF(ROUND(E18,0)=0,"OK","REVISAR") -> OK
A19: 15 | B19: Inversión territorializada ≤ ejecución total (USD) | C19: =F1_Presupuesto_PEP!N10 -> 2728350 | D19: =P2_Focalizacion!P19 -> 735000 | E19: =D19-C19 -> -1993350 | F19: =IF(D19<=C19,"OK","REVISAR") -> OK
A20: 16 | B20: Procesos RACI sin una única «A» | C20: 0 | D20: =COUNTIF(A1_RACI!J5:J40,"REVISAR") -> 0 | E20: =D20-C20 -> 0 | F20: =IF(ROUND(E20,0)=0,"OK","REVISAR") -> OK
B22: Resultado global | C22: =IF(COUNTIF(F5:F20,"REVISAR")=0,"TODOS LOS CONTROLES OK","REVISAR "&COUNTIF(F5:F20,"REVISAR")&" CONTROL(ES)") -> TODOS LOS CONTROLES OK

Sheet P1_Resultados
A1: P1 · Matriz de resultados e indicadores (marco lógico ilustrativo)
A2: DATOS SIMULADOS con fines de demostración metodológica — no son cifras reales del BID ni de la Dirección de Integración.
A3: Meta esperada al corte: acumulativa = interpolación lineal dentro del año · anual = meta × fracción del año · nivel = meta del año. Cumplimiento = valor actual / esperado. Los indicadores sin medición en el período quedan «Sin dato».
A4: ID | B4: Nivel | C4: Indicador | D4: Unidad | E4: Comp. | F4: Línea base | G4: Tipo de meta | H4: Meta año 1 | I4: Meta año 2 | J4: Meta año 3 | K4: Meta año 4 | L4: Meta año 5 | M4: Meta final | N4: Valor actual | O4: Esperado al corte | P4: Cumplimiento | Q4: Semáforo | R4: Fuente de verificación | S4: Frecuencia | T4: Responsable
A5: I-01 | B5: Resultado | C5: Beneficiarios que continúan en educación postsecundaria al 2.º año | D5: % | E5: C2 | F5: 0.7 | G5: Nivel | H5: 0.7 | I5: 0.72 | J5: 0.76 | K5: 0.81 | L5: 0.85 | M5: =L5 -> 0.85 | O5: =IF(G5="Nivel",INDEX(H5:L5,Anio_Programa),IF(G5="Anual",INDEX(H5:L5,Anio_Programa)*Frac_Anio,IF(Anio_Programa=1,F5,INDEX(H5:L5,Anio_Programa-1))+(INDEX(H5:L5,Anio_Programa)-IF(Anio_Programa=1,F5,INDEX(H5:L5,Anio_Programa-1)))*Frac_Anio)) -> 0.7 | P5: =IF(N5="","Sin dato",IF(O5=0,"n/a",N5/O5)) -> Sin dato | Q5: =IF(NOT(ISNUMBER(P5)),"Sin dato",IF(P5>=Umbral_Verde,"Verde",IF(P5>=Umbral_Amarillo,"Amarillo","Rojo"))) -> Sin dato | R5: Sistema de información de trayectorias | S5: Anual | T5: Esp. Planificación, M&S
A6: I-02 | B6: Resultado | C6: Beneficiarios que se gradúan en el tiempo previsto | D6: % | E6: C2 | F6: 0.4 | G6: Nivel | H6: 0.4 | I6: 0.42 | J6: 0.48 | K6: 0.54 | L6: 0.6 | M6: =L6 -> 0.6 | O6: =IF(G6="Nivel",INDEX(H6:L6,Anio_Programa),IF(G6="Anual",INDEX(H6:L6,Anio_Programa)*Frac_Anio,IF(Anio_Programa=1,F6,INDEX(H6:L6,Anio_Programa-1))+(INDEX(H6:L6,Anio_Programa)-IF(Anio_Programa=1,F6,INDEX(H6:L6,Anio_Programa-1)))*Frac_Anio)) -> 0.4 | P6: =IF(N6="","Sin dato",IF(O6=0,"n/a",N6/O6)) -> Sin dato | Q6: =IF(NOT(ISNUMBER(P6)),"Sin dato",IF(P6>=Umbral_Verde,"Verde",IF(P6>=Umbral_Amarillo,"Amarillo","Rojo"))) -> Sin dato | R6: Registros de las instituciones | S6: Anual | T6: Esp. Planificación, M&S
A7: I-03 | B7: Resultado | C7: Personas graduadas vinculadas al empleo formal en 12 meses | D7: % | E7: C3 | F7: 0.25 | G7: Nivel | H7: 0.25 | I7: 0.25 | J7: 0.3 | K7: 0.38 | L7: 0.45 | M7: =L7 -> 0.45 | O7: =IF(G7="Nivel",INDEX(H7:L7,Anio_Programa),IF(G7="Anual",INDEX(H7:L7,Anio_Programa)*Frac_Anio,IF(Anio_Programa=1,F7,INDEX(H7:L7,Anio_Programa-1))+(INDEX(H7:L7,Anio_Programa)-IF(Anio_Programa=1,F7,INDEX(H7:L7,Anio_Programa-1)))*Frac_Anio)) -> 0.25 | P7: =IF(N7="","Sin dato",IF(O7=0,"n/a",N7/O7)) -> Sin dato | Q7: =IF(NOT(ISNUMBER(P7)),"Sin dato",IF(P7>=Umbral_Verde,"Verde",IF(P7>=Umbral_Amarillo,"Amarillo","Rojo"))) -> Sin dato | R7: Encuesta de seguimiento y registros de empleo | S7: Anual | T7: Esp. Planificación, M&S
A8: P-01 | B8: Producto | C8: Estudiantes de educación media con orientación vocacional (acum.) | D8: personas | E8: C1 | F8: 0 | G8: Acumulativa | H8: 4000 | I8: 12000 | J8: 24000 | K8: 38000 | L8: 50000 | M8: =L8 -> 50000 | N8: 1650 | O8: =IF(G8="Nivel",INDEX(H8:L8,Anio_Programa),IF(G8="Anual",INDEX(H8:L8,Anio_Programa)*Frac_Anio,IF(Anio_Programa=1,F8,INDEX(H8:L8,Anio_Programa-1))+(INDEX(H8:L8,Anio_Programa)-IF(Anio_Programa=1,F8,INDEX(H8:L8,Anio_Programa-1)))*Frac_Anio)) -> 1971.2526 | P8: =IF(N8="","Sin dato",IF(O8=0,"n/a",N8/O8)) -> 0.83703125 | Q8: =IF(NOT(ISNUMBER(P8)),"Sin dato",IF(P8>=Umbral_Verde,"Verde",IF(P8>=Umbral_Amarillo,"Amarillo","Rojo"))) -> Amarillo | R8: Registro de participantes | S8: Mensual | T8: Esp. Social
A9: P-02 | B9: Producto | C9: Jóvenes beneficiarios con apoyo y acompañamiento (acum.) | D9: personas | E9: C2 | F9: 0 | G9: Acumulativa | H9: 6000 | I9: 16000 | J9: 30000 | K9: 46000 | L9: 60000 | M9: =L9 -> 60000 | N9: =P2_Focalizacion!G19 -> 2380 | O9: =IF(G9="Nivel",INDEX(H9:L9,Anio_Programa),IF(G9="Anual",INDEX(H9:L9,Anio_Programa)*Frac_Anio,IF(Anio_Programa=1,F9,INDEX(H9:L9,Anio_Programa-1))+(INDEX(H9:L9,Anio_Programa)-IF(Anio_Programa=1,F9,INDEX(H9:L9,Anio_Programa-1)))*Frac_Anio)) -> 2956.8789 | P9: =IF(N9="","Sin dato",IF(O9=0,"n/a",N9/O9)) -> 0.80490278 | Q9: =IF(NOT(ISNUMBER(P9)),"Sin dato",IF(P9>=Umbral_Verde,"Verde",IF(P9>=Umbral_Amarillo,"Amarillo","Rojo"))) -> Amarillo | R9: P2_Focalizacion | S9: Mensual | T9: Esp. Social
A10: P-03 | B10: Producto | C10: Madres jóvenes atendidas (acum.) | D10: personas | E10: C2 | F10: 0 | G10: Acumulativa | H10: 540 | I10: 1440 | J10: 2700 | K10: 4140 | L10: 5400 | M10: =L10 -> 5400 | N10: =P2_Focalizacion!H19 -> 223 | O10: =IF(G10="Nivel",INDEX(H10:L10,Anio_Programa),IF(G10="Anual",INDEX(H10:L10,Anio_Programa)*Frac_Anio,IF(Anio_Programa=1,F10,INDEX(H10:L10,Anio_Programa-1))+(INDEX(H10:L10,Anio_Programa)-IF(Anio_Programa=1,F10,INDEX(H10:L10,Anio_Programa-1)))*Frac_Anio)) -> 266.1191 | P10: =IF(N10="","Sin dato",IF(O10=0,"n/a",N10/O10)) -> 0.83797068 | Q10: =IF(NOT(ISNUMBER(P10)),"Sin dato",IF(P10>=Umbral_Verde,"Verde",IF(P10>=Umbral_Amarillo,"Amarillo","Rojo"))) -> Amarillo | R10: P2_Focalizacion | S10: Mensual | T10: Esp. Social
A11: P-04 | B11: Producto | C11: Personas con discapacidad atendidas (acum.) | D11: personas | E11: C2 | F11: 0 | G11: Acumulativa | H11: 240 | I11: 640 | J11: 1200 | K11: 1840 | L11: 2400 | M11: =L11 -> 2400 | N11: =P2_Focalizacion!I19 -> 90 | O11: =IF(G11="Nivel",INDEX(H11:L11,Anio_Programa),IF(G11="Anual",INDEX(H11:L11,Anio_Programa)*Frac_Anio,IF(Anio_Programa=1,F11,INDEX(H11:L11,Anio_Programa-1))+(INDEX(H11:L11,Anio_Programa)-IF(Anio_Programa=1,F11,INDEX(H11:L11,Anio_Programa-1)))*Frac_Anio)) -> 118.27515 | P11: =IF(N11="","Sin dato",IF(O11=0,"n/a",N11/O11)) -> 0.7609375 | Q11: =IF(NOT(ISNUMBER(P11)),"Sin dato",IF(P11>=Umbral_Verde,"Verde",IF(P11>=Umbral_Amarillo,"Amarillo","Rojo"))) -> Amarillo | R11: P2_Focalizacion | S11: Mensual | T11: Esp. Social
A12: P-05 | B12: Producto | C12: Personas retornadas atendidas (acum.) | D12: personas | E12: C2 | F12: 0 | G12: Acumulativa | H12: 180 | I12: 480 | J12: 900 | K12: 1380 | L12: 1800 | M12: =L12 -> 1800 | N12: =P2_Focalizacion!J19 -> 75 | O12: =IF(G12="Nivel",INDEX(H12:L12,Anio_Programa),IF(G12="Anual",INDEX(H12:L12,Anio_Programa)*Frac_Anio,IF(Anio_Programa=1,F12,INDEX(H12:L12,Anio_Programa-1))+(INDEX(H12:L12,Anio_Programa)-IF(Anio_Programa=1,F12,INDEX(H12:L12,Anio_Programa-1)))*Frac_Anio)) -> 88.706366 | P12: =IF(N12="","Sin dato",IF(O12=0,"n/a",N12/O12)) -> 0.84548611 | Q12: =IF(NOT(ISNUMBER(P12)),"Sin dato",IF(P12>=Umbral_Verde,"Verde",IF(P12>=Umbral_Amarillo,"Amarillo","Rojo"))) -> Amarillo | R12: P2_Focalizacion | S12: Mensual | T12: Esp. Social
A13: P-06 | B13: Producto | C13: Convenios firmados con instituciones de educación postsecundaria (acum.) | D13: convenios | E13: C4 | F13: 0 | G13: Acumulativa | H13: 8 | I13: 20 | J13: 30 | K13: 36 | L13: 40 | M13: =L13 -> 40 | N13: 6 | O13: =IF(G13="Nivel",INDEX(H13:L13,Anio_Programa),IF(G13="Anual",INDEX(H13:L13,Anio_Programa)*Frac_Anio,IF(Anio_Programa=1,F13,INDEX(H13:L13,Anio_Programa-1))+(INDEX(H13:L13,Anio_Programa)-IF(Anio_Programa=1,F13,INDEX(H13:L13,Anio_Programa-1)))*Frac_Anio)) -> 3.9425051 | P13: =IF(N13="","Sin dato",IF(O13=0,"n/a",N13/O13)) -> 1.521875 | Q13: =IF(NOT(ISNUMBER(P13)),"Sin dato",IF(P13>=Umbral_Verde,"Verde",IF(P13>=Umbral_Amarillo,"Amarillo","Rojo"))) -> Verde | R13: Convenios archivados | S13: Mensual | T13: Esp. Social
A14: P-07 | B14: Producto | C14: Empleadores aliados activos (acum.) | D14: empleadores | E14: C3 | F14: 0 | G14: Acumulativa | H14: 20 | I14: 60 | J14: 120 | K14: 180 | L14: 250 | M14: =L14 -> 250 | N14: 7 | O14: =IF(G14="Nivel",INDEX(H14:L14,Anio_Programa),IF(G14="Anual",INDEX(H14:L14,Anio_Programa)*Frac_Anio,IF(Anio_Programa=1,F14,INDEX(H14:L14,Anio_Programa-1))+(INDEX(H14:L14,Anio_Programa)-IF(Anio_Programa=1,F14,INDEX(H14:L14,Anio_Programa-1)))*Frac_Anio)) -> 9.8562628 | P14: =IF(N14="","Sin dato",IF(O14=0,"n/a",N14/O14)) -> 0.71020833 | Q14: =IF(NOT(ISNUMBER(P14)),"Sin dato",IF(P14>=Umbral_Verde,"Verde",IF(P14>=Umbral_Amarillo,"Amarillo","Rojo"))) -> Amarillo | R14: Alianzas firmadas | S14: Mensual | T14: Esp. Social
A15: P-08 | B15: Producto | C15: Instituciones con plan de fortalecimiento en implementación (acum.) | D15: instituciones | E15: C4 | F15: 0 | G15: Acumulativa | H15: 3 | I15: 12 | J15: 25 | K15: 35 | L15: 40 | M15: =L15 -> 40 | N15: 0 | O15: =IF(G15="Nivel",INDEX(H15:L15,Anio_Programa),IF(G15="Anual",INDEX(H15:L15,Anio_Programa)*Frac_Anio,IF(Anio_Programa=1,F15,INDEX(H15:L15,Anio_Programa-1))+(INDEX(H15:L15,Anio_Programa)-IF(Anio_Programa=1,F15,INDEX(H15:L15,Anio_Programa-1)))*Frac_Anio)) -> 1.4784394 | P15: =IF(N15="","Sin dato",IF(O15=0,"n/a",N15/O15)) -> 0 | Q15: =IF(NOT(ISNUMBER(P15)),"Sin dato",IF(P15>=Umbral_Verde,"Verde",IF(P15>=Umbral_Amarillo,"Amarillo","Rojo"))) -> Rojo | R15: Informes de capacitación | S15: Trimestral | T15: Esp. Social
A16: P-09 | B16: Producto | C16: Sistema de información de trayectorias: módulos operativos | D16: % | E16: C4 | F16: 0 | G16: Acumulativa | H16: 0.8 | I16: 1 | J16: 1 | K16: 1 | L16: 1 | M16: =L16 -> 1 | N16: 0.35 | O16: =IF(G16="Nivel",INDEX(H16:L16,Anio_Programa),IF(G16="Anual",INDEX(H16:L16,Anio_Programa)*Frac_Anio,IF(Anio_Programa=1,F16,INDEX(H16:L16,Anio_Programa-1))+(INDEX(H16:L16,Anio_Programa)-IF(Anio_Programa=1,F16,INDEX(H16:L16,Anio_Programa-1)))*Frac_Anio)) -> 0.39425051 | P16: =IF(N16="","Sin dato",IF(O16=0,"n/a",N16/O16)) -> 0.88776042 | Q16: =IF(NOT(ISNUMBER(P16)),"Sin dato",IF(P16>=Umbral_Verde,"Verde",IF(P16>=Umbral_Amarillo,"Amarillo","Rojo"))) -> Amarillo | R16: Actas de recepción por módulo | S16: Mensual | T16: Esp. Planificación, M&S
A17: G-01 | B17: Gestión | C17: Ejecución financiera acumulada del Programa (% del total) | D17: % | E17: Todos | F17: 0 | G17: Acumulativa | H17: =SUM(F1_Presupuesto_PEP!$G$10:G$10)/Total_Programa -> 0.0625 | I17: =SUM(F1_Presupuesto_PEP!$G$10:H$10)/Total_Programa -> 0.26865385 | J17: =SUM(F1_Presupuesto_PEP!$G$10:I$10)/Total_Programa -> 0.54990385 | K17: =SUM(F1_Presupuesto_PEP!$G$10:J$10)/Total_Programa -> 0.8125 | L17: =SUM(F1_Presupuesto_PEP!$G$10:K$10)/Total_Programa -> 1 | M17: =L17 -> 1 | N17: =F1_Presupuesto_PEP!O10 -> 0.026234135 | O17: =IF(G17="Nivel",INDEX(H17:L17,Anio_Programa),IF(G17="Anual",INDEX(H17:L17,Anio_Programa)*Frac_Anio,IF(Anio_Programa=1,F17,INDEX(H17:L17,Anio_Programa-1))+(INDEX(H17:L17,Anio_Programa)-IF(Anio_Programa=1,F17,INDEX(H17:L17,Anio_Programa-1)))*Frac_Anio)) -> 0.030800821 | P17: =IF(N17="","Sin dato",IF(O17=0,"n/a",N17/O17)) -> 0.8517349 | Q17: =IF(NOT(ISNUMBER(P17)),"Sin dato",IF(P17>=Umbral_Verde,"Verde",IF(P17>=Umbral_Amarillo,"Amarillo","Rojo"))) -> Amarillo | R17: F1_Presupuesto_PEP | S17: Mensual | T17: Esp. Financiero
A18: G-02 | B18: Gestión | C18: Avance físico ponderado del POA vigente | D18: % | E18: Todos | F18: 0 | G18: Anual | H18: 1 | I18: 1 | J18: 1 | K18: 1 | L18: 1 | M18: =L18 -> 1 | N18: =P1_Avance_FF!F10 -> 0.44792308 | O18: =IF(G18="Nivel",INDEX(H18:L18,Anio_Programa),IF(G18="Anual",INDEX(H18:L18,Anio_Programa)*Frac_Anio,IF(Anio_Programa=1,F18,INDEX(H18:L18,Anio_Programa-1))+(INDEX(H18:L18,Anio_Programa)-IF(Anio_Programa=1,F18,INDEX(H18:L18,Anio_Programa-1)))*Frac_Anio)) -> 0.49281314 | P18: =IF(N18="","Sin dato",IF(O18=0,"n/a",N18/O18)) -> 0.90891058 | Q18: =IF(NOT(ISNUMBER(P18)),"Sin dato",IF(P18>=Umbral_Verde,"Verde",IF(P18>=Umbral_Amarillo,"Amarillo","Rojo"))) -> Verde | R18: P1_POA | S18: Mensual | T18: Esp. Planificación, M&S
A19: G-03 | B19: Gestión | C19: Procesos del Plan de Adquisiciones con contrato firmado | D19: % | E19: Todos | F19: 0 | G19: Nivel | H19: 0.9 | I19: 0.9 | J19: 0.9 | K19: 0.9 | L19: 0.9 | M19: =L19 -> 0.9 | N19: =COUNTIF(F4_Plan_Adquisiciones!$I$5:$I$200,"Contratado")/COUNTIF(F4_Plan_Adquisiciones!$A$5:$A$200,"PA-*") -> 0.8 | O19: =IF(G19="Nivel",INDEX(H19:L19,Anio_Programa),IF(G19="Anual",INDEX(H19:L19,Anio_Programa)*Frac_Anio,IF(Anio_Programa=1,F19,INDEX(H19:L19,Anio_Programa-1))+(INDEX(H19:L19,Anio_Programa)-IF(Anio_Programa=1,F19,INDEX(H19:L19,Anio_Programa-1)))*Frac_Anio)) -> 0.9 | P19: =IF(N19="","Sin dato",IF(O19=0,"n/a",N19/O19)) -> 0.88888889 | Q19: =IF(NOT(ISNUMBER(P19)),"Sin dato",IF(P19>=Umbral_Verde,"Verde",IF(P19>=Umbral_Amarillo,"Amarillo","Rojo"))) -> Amarillo | R19: F4_Plan_Adquisiciones | S19: Mensual | T19: Esp. Adquisiciones
A20: G-04 | B20: Gestión | C20: Informes mensuales entregados a tiempo | D20: % | E20: UGP | F20: 1 | G20: Nivel | H20: 1 | I20: 1 | J20: 1 | K20: 1 | L20: 1 | M20: =L20 -> 1 | N20: =COUNTIF(A5_Calendario_Informes!$F$5:$F$30,"Entregado a tiempo")/COUNTIF(A5_Calendario_Informes!$F$5:$F$30,"Entregado*") -> 0.8 | O20: =IF(G20="Nivel",INDEX(H20:L20,Anio_Programa),IF(G20="Anual",INDEX(H20:L20,Anio_Programa)*Frac_Anio,IF(Anio_Programa=1,F20,INDEX(H20:L20,Anio_Programa-1))+(INDEX(H20:L20,Anio_Programa)-IF(Anio_Programa=1,F20,INDEX(H20:L20,Anio_Programa-1)))*Frac_Anio)) -> 1 | P20: =IF(N20="","Sin dato",IF(O20=0,"n/a",N20/O20)) -> 0.8 | Q20: =IF(NOT(ISNUMBER(P20)),"Sin dato",IF(P20>=Umbral_Verde,"Verde",IF(P20>=Umbral_Amarillo,"Amarillo","Rojo"))) -> Amarillo | R20: A5_Calendario_Informes | S20: Mensual | T20: Coordinador General
A21: G-05 | B21: Gestión | C21: Compromisos con el BID cumplidos en plazo | D21: % | E21: UGP | F21: 1 | G21: Nivel | H21: 1 | I21: 1 | J21: 1 | K21: 1 | L21: 1 | M21: =L21 -> 1 | N21: =IFERROR(COUNTIF(A2_Misiones_BID!$I$14:$I$100,"Sí")/(COUNTIF(A2_Misiones_BID!$G$14:$G$100,"Cumplido")+COUNTIFS(A2_Misiones_BID!$E$14:$E$100,"<"&Fecha_Corte,A2_Misiones_BID!$G$14:$G$100,"<>Cumplido",A2_Misiones_BID!$A$14:$A$100,"CM-*")),"") -> 0.625 | O21: =IF(G21="Nivel",INDEX(H21:L21,Anio_Programa),IF(G21="Anual",INDEX(H21:L21,Anio_Programa)*Frac_Anio,IF(Anio_Programa=1,F21,INDEX(H21:L21,Anio_Programa-1))+(INDEX(H21:L21,Anio_Programa)-IF(Anio_Programa=1,F21,INDEX(H21:L21,Anio_Programa-1)))*Frac_Anio)) -> 1 | P21: =IF(N21="","Sin dato",IF(O21=0,"n/a",N21/O21)) -> 0.625 | Q21: =IF(NOT(ISNUMBER(P21)),"Sin dato",IF(P21>=Umbral_Verde,"Verde",IF(P21>=Umbral_Amarillo,"Amarillo","Rojo"))) -> Rojo | R21: A2_Misiones_BID | S21: Por misión | T21: Coordinador General
A22: G-06 | B22: Gestión | C22: Quejas atendidas dentro del plazo del mecanismo | D22: % | E22: C5 | F22: 0.9 | G22: Nivel | H22: 0.9 | I22: 0.9 | J22: 0.9 | K22: 0.9 | L22: 0.9 | M22: =L22 -> 0.9 | N22: 0.88 | O22: =IF(G22="Nivel",INDEX(H22:L22,Anio_Programa),IF(G22="Anual",INDEX(H22:L22,Anio_Programa)*Frac_Anio,IF(Anio_Programa=1,F22,INDEX(H22:L22,Anio_Programa-1))+(INDEX(H22:L22,Anio_Programa)-IF(Anio_Programa=1,F22,INDEX(H22:L22,Anio_Programa-1)))*Frac_Anio)) -> 0.9 | P22: =IF(N22="","Sin dato",IF(O22=0,"n/a",N22/O22)) -> 0.97777778 | Q22: =IF(NOT(ISNUMBER(P22)),"Sin dato",IF(P22>=Umbral_Verde,"Verde",IF(P22>=Umbral_Amarillo,"Amarillo","Rojo"))) -> Verde | R22: Registro del mecanismo de quejas | S22: Mensual | T22: Esp. Social

Sheet P1_POA
A1: P1 · Plan Operativo Anual (POA) e hitos — avance físico y financiero por actividad
A2: DATOS SIMULADOS con fines de demostración metodológica — no son cifras reales del BID ni de la Dirección de Integración.
A3: Valor ganado: EV = presupuesto × % avance físico · PV = presupuesto × % planificado a la fecha de corte · AC = ejecutado (libro F2). SPI = EV/PV · CPI = EV/AC.
A4: ID | B4: Comp. | C4: Actividad | D4: Responsable | E4: Inicio | F4: Fin | G4: Presupuesto POA USD | H4: % avance físico | I4: % planificado a corte | J4: Ejecutado USD (AC) | K4: % ejecución financiera | L4: EV USD | M4: PV USD | N4: SPI | O4: CPI | P4: Días de atraso | Q4: Estado | R4: Semáforo | S4: Hito / entregable
A5: C1-01 | B5: C1 | C5: Diseño del modelo de captación y orientación vocacional | D5: Esp. Social | E5: 46402 | F5: 46477 | G5: 130000 | H5: 1 | I5: =IF(Fecha_Corte<=E5,0,IF(Fecha_Corte>=F5,1,(Fecha_Corte-E5)/(F5-E5))) -> 1 | J5: =SUMIFS(F2_Ejecucion!$J$5:$J$500,F2_Ejecucion!$D$5:$D$500,A5) -> 124000 | K5: =IF(G5=0,0,J5/G5) -> 0.95384615 | L5: =G5*H5 -> 130000 | M5: =G5*I5 -> 130000 | N5: =IF(M5=0,"n/a",L5/M5) -> 1 | O5: =IF(J5=0,"n/a",L5/J5) -> 1.0483871 | P5: =IF(H5>=1,0,MAX(0,Fecha_Corte-F5)) -> 0 | Q5: =IF(H5>=1,"Completada",IF(Fecha_Corte<E5,"No iniciada",IF(Fecha_Corte>F5,"Vencida sin completar",IF(NOT(ISNUMBER(N5)),"En curso",IF(N5>=EVM_Verde,"En curso a tiempo",IF(N5>=EVM_Amarillo,"En curso con retraso leve","En curso con retraso crítico")))))) -> Completada | R5: =IF(H5>=1,"Verde",IF(NOT(ISNUMBER(N5)),"Gris",IF(N5>=EVM_Verde,"Verde",IF(N5>=EVM_Amarillo,"Amarillo","Rojo")))) -> Verde | S5: Modelo de captación aprobado
A6: C1-02 | B6: C1 | C6: Convenios con centros de educación media | D6: Esp. Social | E6: 46419 | F6: 46538 | G6: 160000 | H6: 0.9 | I6: =IF(Fecha_Corte<=E6,0,IF(Fecha_Corte>=F6,1,(Fecha_Corte-E6)/(F6-E6))) -> 1 | J6: =SUMIFS(F2_Ejecucion!$J$5:$J$500,F2_Ejecucion!$D$5:$D$500,A6) -> 128000 | K6: =IF(G6=0,0,J6/G6) -> 0.8 | L6: =G6*H6 -> 144000 | M6: =G6*I6 -> 160000 | N6: =IF(M6=0,"n/a",L6/M6) -> 0.9 | O6: =IF(J6=0,"n/a",L6/J6) -> 1.125 | P6: =IF(H6>=1,0,MAX(0,Fecha_Corte-F6)) -> 30 | Q6: =IF(H6>=1,"Completada",IF(Fecha_Corte<E6,"No iniciada",IF(Fecha_Corte>F6,"Vencida sin completar",IF(NOT(ISNUMBER(N6)),"En curso",IF(N6>=EVM_Verde,"En curso a tiempo",IF(N6>=EVM_Amarillo,"En curso con retraso leve","En curso con retraso crítico")))))) -> Vencida sin completar | R6: =IF(H6>=1,"Verde",IF(NOT(ISNUMBER(N6)),"Gris",IF(N6>=EVM_Verde,"Verde",IF(N6>=EVM_Amarillo,"Amarillo","Rojo")))) -> Amarillo | S6: Convenios firmados con centros educativos
A7: C1-03 | B7: C1 | C7: Campaña nacional de difusión | D7: Esp. Planificación, M&S | E7: 46447 | F7: 46630 | G7: 310000 | H7: 0.58 | I7: =IF(Fecha_Corte<=E7,0,IF(Fecha_Corte>=F7,1,(Fecha_Corte-E7)/(F7-E7))) -> 0.66120219 | J7: =SUMIFS(F2_Ejecucion!$J$5:$J$500,F2_Ejecucion!$D$5:$D$500,A7) -> 162500 | K7: =IF(G7=0,0,J7/G7) -> 0.52419355 | L7: =G7*H7 -> 179800 | M7: =G7*I7 -> 204972.68 | N7: =IF(M7=0,"n/a",L7/M7) -> 0.87719008 | O7: =IF(J7=0,"n/a",L7/J7) -> 1.1064615 | P7: =IF(H7>=1,0,MAX(0,Fecha_Corte-F7)) -> 0 | Q7: =IF(H7>=1,"Completada",IF(Fecha_Corte<E7,"No iniciada",IF(Fecha_Corte>F7,"Vencida sin completar",IF(NOT(ISNUMBER(N7)),"En curso",IF(N7>=EVM_Verde,"En curso a tiempo",IF(N7>=EVM_Amarillo,"En curso con retraso leve","En curso con retraso crítico")))))) -> En curso con retraso leve | R7: =IF(H7>=1,"Verde",IF(NOT(ISNUMBER(N7)),"Gris",IF(N7>=EVM_Verde,"Verde",IF(N7>=EVM_Amarillo,"Amarillo","Rojo")))) -> Amarillo | S7: Campaña lanzada (fase 1)
A8: C1-04 | B8: C1 | C8: Plataforma de registro de aspirantes | D8: Esp. Planificación, M&S | E8: 46433 | F8: 46583 | G8: 290000 | H8: 0.78 | I8: =IF(Fecha_Corte<=E8,0,IF(Fecha_Corte>=F8,1,(Fecha_Corte-E8)/(F8-E8))) -> 0.9 | J8: =SUMIFS(F2_Ejecucion!$J$5:$J$500,F2_Ejecucion!$D$5:$D$500,A8) -> 199100 | K8: =IF(G8=0,0,J8/G8) -> 0.68655172 | L8: =G8*H8 -> 226200 | M8: =G8*I8 -> 261000 | N8: =IF(M8=0,"n/a",L8/M8) -> 0.86666667 | O8: =IF(J8=0,"n/a",L8/J8) -> 1.1361125 | P8: =IF(H8>=1,0,MAX(0,Fecha_Corte-F8)) -> 0 | Q8: =IF(H8>=1,"Completada",IF(Fecha_Corte<E8,"No iniciada",IF(Fecha_Corte>F8,"Vencida sin completar",IF(NOT(ISNUMBER(N8)),"En curso",IF(N8>=EVM_Verde,"En curso a tiempo",IF(N8>=EVM_Amarillo,"En curso con retraso leve","En curso con retraso crítico")))))) -> En curso con retraso leve | R8: =IF(H8>=1,"Verde",IF(NOT(ISNUMBER(N8)),"Gris",IF(N8>=EVM_Verde,"Verde",IF(N8>=EVM_Amarillo,"Amarillo","Rojo")))) -> Amarillo | S8: Plataforma en producción
A9: C1-05 | B9: C1 | C9: Ferias de orientación departamentales | D9: Esp. Social | E9: 46539 | F9: 46721 | G9: 140000 | H9: 0.14 | I9: =IF(Fecha_Corte<=E9,0,IF(Fecha_Corte>=F9,1,(Fecha_Corte-E9)/(F9-E9))) -> 0.15934066 | J9: =SUMIFS(F2_Ejecucion!$J$5:$J$500,F2_Ejecucion!$D$5:$D$500,A9) -> 14000 | K9: =IF(G9=0,0,J9/G9) -> 0.1 | L9: =G9*H9 -> 19600 | M9: =G9*I9 -> 22307.692 | N9: =IF(M9=0,"n/a",L9/M9) -> 0.87862069 | O9: =IF(J9=0,"n/a",L9/J9) -> 1.4 | P9: =IF(H9>=1,0,MAX(0,Fecha_Corte-F9)) -> 0 | Q9: =IF(H9>=1,"Completada",IF(Fecha_Corte<E9,"No iniciada",IF(Fecha_Corte>F9,"Vencida sin completar",IF(NOT(ISNUMBER(N9)),"En curso",IF(N9>=EVM_Verde,"En curso a tiempo",IF(N9>=EVM_Amarillo,"En curso con retraso leve","En curso con retraso crítico")))))) -> En curso con retraso leve | R9: =IF(H9>=1,"Verde",IF(NOT(ISNUMBER(N9)),"Gris",IF(N9>=EVM_Verde,"Verde",IF(N9>=EVM_Amarillo,"Amarillo","Rojo")))) -> Amarillo | S9: Primera feria realizada
A10: C2-01 | B10: C2 | C10: Esquema de apoyos y criterios de elegibilidad | D10: Esp. Social | E10: 46402 | F10: 46461 | G10: 70000 | H10: 1 | I10: =IF(Fecha_Corte<=E10,0,IF(Fecha_Corte>=F10,1,(Fecha_Corte-E10)/(F10-E10))) -> 1 | J10: =SUMIFS(F2_Ejecucion!$J$5:$J$500,F2_Ejecucion!$D$5:$D$500,A10) -> 63800 | K10: =IF(G10=0,0,J10/G10) -> 0.91142857 | L10: =G10*H10 -> 70000 | M10: =G10*I10 -> 70000 | N10: =IF(M10=0,"n/a",L10/M10) -> 1 | O10: =IF(J10=0,"n/a",L10/J10) -> 1.0971787 | P10: =IF(H10>=1,0,MAX(0,Fecha_Corte-F10)) -> 0 | Q10: =IF(H10>=1,"Completada",IF(Fecha_Corte<E10,"No iniciada",IF(Fecha_Corte>F10,"Vencida sin completar",IF(NOT(ISNUMBER(N10)),"En curso",IF(N10>=EVM_Verde,"En curso a tiempo",IF(N10>=EVM_Amarillo,"En curso con retraso leve","En curso con retraso crítico")))))) -> Completada | R10: =IF(H10>=1,"Verde",IF(NOT(ISNUMBER(N10)),"Gris",IF(N10>=EVM_Verde,"Verde",IF(N10>=EVM_Amarillo,"Amarillo","Rojo")))) -> Verde | S10: Esquema de apoyos aprobado (MOP)
A11: C2-02 | B11: C2 | C11: Selección de la primera cohorte | D11: Esp. Social | E11: 46447 | F11: 46553 | G11: 180000 | H11: 0.85 | I11: =IF(Fecha_Corte<=E11,0,IF(Fecha_Corte>=F11,1,(Fecha_Corte-E11)/(F11-E11))) -> 1 | J11: =SUMIFS(F2_Ejecucion!$J$5:$J$500,F2_Ejecucion!$D$5:$D$500,A11) -> 150000 | K11: =IF(G11=0,0,J11/G11) -> 0.83333333 | L11: =G11*H11 -> 153000 | M11: =G11*I11 -> 180000 | N11: =IF(M11=0,"n/a",L11/M11) -> 0.85 | O11: =IF(J11=0,"n/a",L11/J11) -> 1.02 | P11: =IF(H11>=1,0,MAX(0,Fecha_Corte-F11)) -> 15 | Q11: =IF(H11>=1,"Completada",IF(Fecha_Corte<E11,"No iniciada",IF(Fecha_Corte>F11,"Vencida sin completar",IF(NOT(ISNUMBER(N11)),"En curso",IF(N11>=EVM_Verde,"En curso a tiempo",IF(N11>=EVM_Amarillo,"En curso con retraso leve","En curso con retraso crítico")))))) -> Vencida sin completar | R11: =IF(H11>=1,"Verde",IF(NOT(ISNUMBER(N11)),"Gris",IF(N11>=EVM_Verde,"Verde",IF(N11>=EVM_Amarillo,"Amarillo","Rojo")))) -> Amarillo | S11: Cohorte 1 seleccionada
A12: C2-03 | B12: C2 | C12: Apoyos económicos primera cohorte | D12: Esp. Financiero | E12: 46478 | F12: 46736 | G12: 900000 | H12: 0.4 | I12: =IF(Fecha_Corte<=E12,0,IF(Fecha_Corte>=F12,1,(Fecha_Corte-E12)/(F12-E12))) -> 0.34883721 | J12: =SUMIFS(F2_Ejecucion!$J$5:$J$500,F2_Ejecucion!$D$5:$D$500,A12) -> 330000 | K12: =IF(G12=0,0,J12/G12) -> 0.36666667 | L12: =G12*H12 -> 360000 | M12: =G12*I12 -> 313953.49 | N12: =IF(M12=0,"n/a",L12/M12) -> 1.1466667 | O12: =IF(J12=0,"n/a",L12/J12) -> 1.0909091 | P12: =IF(H12>=1,0,MAX(0,Fecha_Corte-F12)) -> 0 | Q12: =IF(H12>=1,"Completada",IF(Fecha_Corte<E12,"No iniciada",IF(Fecha_Corte>F12,"Vencida sin completar",IF(NOT(ISNUMBER(N12)),"En curso",IF(N12>=EVM_Verde,"En curso a tiempo",IF(N12>=EVM_Amarillo,"En curso con retraso leve","En curso con retraso crítico")))))) -> En curso a tiempo | R12: =IF(H12>=1,"Verde",IF(NOT(ISNUMBER(N12)),"Gris",IF(N12>=EVM_Verde,"Verde",IF(N12>=EVM_Amarillo,"Amarillo","Rojo")))) -> Verde | S12: Primer pago de apoyos
A13: C2-04 | B13: C2 | C13: Acompañamiento socioeducativo (tutorías) | D13: Esp. Social | E13: 46492 | F13: 46736 | G13: 420000 | H13: 0.3 | I13: =IF(Fecha_Corte<=E13,0,IF(Fecha_Corte>=F13,1,(Fecha_Corte-E13)/(F13-E13))) -> 0.31147541 | J13: =SUMIFS(F2_Ejecucion!$J$5:$J$500,F2_Ejecucion!$D$5:$D$500,A13) -> 138500 | K13: =IF(G13=0,0,J13/G13) -> 0.3297619 | L13: =G13*H13 -> 126000 | M13: =G13*I13 -> 130819.67 | N13: =IF(M13=0,"n/a",L13/M13) -> 0.96315789 | O13: =IF(J13=0,"n/a",L13/J13) -> 0.90974729 | P13: =IF(H13>=1,0,MAX(0,Fecha_Corte-F13)) -> 0 | Q13: =IF(H13>=1,"Completada",IF(Fecha_Corte<E13,"No iniciada",IF(Fecha_Corte>F13,"Vencida sin completar",IF(NOT(ISNUMBER(N13)),"En curso",IF(N13>=EVM_Verde,"En curso a tiempo",IF(N13>=EVM_Amarillo,"En curso con retraso leve","En curso con retraso crítico")))))) -> En curso a tiempo | R13: =IF(H13>=1,"Verde",IF(NOT(ISNUMBER(N13)),"Gris",IF(N13>=EVM_Verde,"Verde",IF(N13>=EVM_Amarillo,"Amarillo","Rojo")))) -> Verde | S13: Tutorías en marcha
A14: C2-05 | B14: C2 | C14: Servicios de accesibilidad para personas con discapacidad | D14: Esp. Social | E14: 46508 | F14: 46736 | G14: 150000 | H14: 0.24 | I14: =IF(Fecha_Corte<=E14,0,IF(Fecha_Corte>=F14,1,(Fecha_Corte-E14)/(F14-E14))) -> 0.26315789 | J14: =SUMIFS(F2_Ejecucion!$J$5:$J$500,F2_Ejecucion!$D$5:$D$500,A14) -> 34000 | K14: =IF(G14=0,0,J14/G14) -> 0.22666667 | L14: =G14*H14 -> 36000 | M14: =G14*I14 -> 39473.684 | N14: =IF(M14=0,"n/a",L14/M14) -> 0.912 | O14: =IF(J14=0,"n/a",L14/J14) -> 1.0588235 | P14: =IF(H14>=1,0,MAX(0,Fecha_Corte-F14)) -> 0 | Q14: =IF(H14>=1,"Completada",IF(Fecha_Corte<E14,"No iniciada",IF(Fecha_Corte>F14,"Vencida sin completar",IF(NOT(ISNUMBER(N14)),"En curso",IF(N14>=EVM_Verde,"En curso a tiempo",IF(N14>=EVM_Amarillo,"En curso con retraso leve","En curso con retraso crítico")))))) -> En curso con retraso leve | R14: =IF(H14>=1,"Verde",IF(NOT(ISNUMBER(N14)),"Gris",IF(N14>=EVM_Verde,"Verde",IF(N14>=EVM_Amarillo,"Amarillo","Rojo")))) -> Amarillo | S14: Servicios de accesibilidad contratados
A15: C2-06 | B15: C2 | C15: Atención a madres jóvenes y personas retornadas | D15: Esp. Social | E15: 46508 | F15: 46736 | G15: 80000 | H15: 0.25 | I15: =IF(Fecha_Corte<=E15,0,IF(Fecha_Corte>=F15,1,(Fecha_Corte-E15)/(F15-E15))) -> 0.26315789 | J15: =SUMIFS(F2_Ejecucion!$J$5:$J$500,F2_Ejecucion!$D$5:$D$500,A15) -> 19000 | K15: =IF(G15=0,0,J15/G15) -> 0.2375 | L15: =G15*H15 -> 20000 | M15: =G15*I15 -> 21052.632 | N15: =IF(M15=0,"n/a",L15/M15) -> 0.95 | O15: =IF(J15=0,"n/a",L15/J15) -> 1.0526316 | P15: =IF(H15>=1,0,MAX(0,Fecha_Corte-F15)) -> 0 | Q15: =IF(H15>=1,"Completada",IF(Fecha_Corte<E15,"No iniciada",IF(Fecha_Corte>F15,"Vencida sin completar",IF(NOT(ISNUMBER(N15)),"En curso",IF(N15>=EVM_Verde,"En curso a tiempo",IF(N15>=EVM_Amarillo,"En curso con retraso leve","En curso con retraso crítico")))))) -> En curso a tiempo | R15: =IF(H15>=1,"Verde",IF(NOT(ISNUMBER(N15)),"Gris",IF(N15>=EVM_Verde,"Verde",IF(N15>=EVM_Amarillo,"Amarillo","Rojo")))) -> Verde | S15: Protocolo de atención aprobado
A16: C3-01 | B16: C3 | C16: Diagnóstico de demanda laboral | D16: Esp. Planificación, M&S | E16: 46419 | F16: 46538 | G16: 195000 | H16: 1 | I16: =IF(Fecha_Corte<=E16,0,IF(Fecha_Corte>=F16,1,(Fecha_Corte-E16)/(F16-E16))) -> 1 | J16: =SUMIFS(F2_Ejecucion!$J$5:$J$500,F2_Ejecucion!$D$5:$D$500,A16) -> 189000 | K16: =IF(G16=0,0,J16/G16) -> 0.96923077 | L16: =G16*H16 -> 195000 | M16: =G16*I16 -> 195000 | N16: =IF(M16=0,"n/a",L16/M16) -> 1 | O16: =IF(J16=0,"n/a",L16/J16) -> 1.031746 | P16: =IF(H16>=1,0,MAX(0,Fecha_Corte-F16)) -> 0 | Q16: =IF(H16>=1,"Completada",IF(Fecha_Corte<E16,"No iniciada",IF(Fecha_Corte>F16,"Vencida sin completar",IF(NOT(ISNUMBER(N16)),"En curso",IF(N16>=EVM_Verde,"En curso a tiempo",IF(N16>=EVM_Amarillo,"En curso con retraso leve","En curso con retraso crítico")))))) -> Completada | R16: =IF(H16>=1,"Verde",IF(NOT(ISNUMBER(N16)),"Gris",IF(N16>=EVM_Verde,"Verde",IF(N16>=EVM_Amarillo,"Amarillo","Rojo")))) -> Verde | S16: Informe de diagnóstico aprobado
... A28: C5-05 | B28: C5 | C28: Comunicación y gestión del conocimiento | D28: Esp. Planificación, M&S | E28: 46447 | F28: 46736 | G28: 80000 | H28: 0.36 | I28: =IF(Fecha_Corte<=E28,0,IF(Fecha_Corte>=F28,1,(Fecha_Corte-E28)/(F28-E28))) -> 0.41868512 | J28: =SUMIFS(F2_Ejecucion!$J$5:$J$500,F2_Ejecucion!$D$5:$D$500,A28) -> 28000 | K28: =IF(G28=0,0,J28/G28) -> 0.35 | L28: =G28*H28 -> 28800 | M28: =G28*I28 -> 33494.81 | N28: =IF(M28=0,"n/a",L28/M28) -> 0.85983471 | O28: =IF(J28=0,"n/a",L28/J28) -> 1.0285714 | P28: =IF(H28>=1,0,MAX(0,Fecha_Corte-F28)) -> 0 | Q28: =IF(H28>=1,"Completada",IF(Fecha_Corte<E28,"No iniciada",IF(Fecha_Corte>F28,"Vencida sin completar",IF(NOT(ISNUMBER(N28)),"En curso",IF(N28>=EVM_Verde,"En curso a tiempo",IF(N28>=EVM_Amarillo,"En curso con retraso leve","En curso con retraso crítico")))))) -> En curso con retraso leve | R28: =IF(H28>=1,"Verde",IF(NOT(ISNUMBER(N28)),"Gris",IF(N28>=EVM_Verde,"Verde",IF(N28>=EVM_Amarillo,"Amarillo","Rojo")))) -> Amarillo | S28: Plan de comunicación implementado

Sheet P1_Avance_FF
A1: P1 · Avance físico y financiero consolidado por componente (POA del año vigente)
A2: DATOS SIMULADOS con fines de demostración metodológica — no son cifras reales del BID ni de la Dirección de Integración.
A3: Lectura: SPI < 1 = atraso físico frente a lo planificado; CPI < 1 = se gastó más de lo que el avance físico justifica.
A4: Comp. | B4: Componente | C4: Presupuesto POA | D4: Ejecutado (AC) | E4: % financiero | F4: % físico ponderado | G4: % planificado | H4: EV | I4: PV | J4: SPI | K4: CPI | L4: Brecha físico − financiero | M4: N.º actividades | N4: N.º con alerta | O4: Semáforo
A5: C1 | B5: Acceso y orientación | C5: =SUMIFS(P1_POA!$G$5:$G$200,P1_POA!$B$5:$B$200,A5) -> 1030000 | D5: =SUMIFS(P1_POA!$J$5:$J$200,P1_POA!$B$5:$B$200,A5) -> 627600 | E5: =IF(C5=0,0,D5/C5) -> 0.60932039 | F5: =IF(C5=0,0,H5/C5) -> 0.6792233 | G5: =IF(C5=0,0,I5/C5) -> 0.75561201 | H5: =SUMIFS(P1_POA!$L$5:$L$200,P1_POA!$B$5:$B$200,A5) -> 699600 | I5: =SUMIFS(P1_POA!$M$5:$M$200,P1_POA!$B$5:$B$200,A5) -> 778280.37 | J5: =IF(I5=0,"n/a",H5/I5) -> 0.89890485 | K5: =IF(D5=0,"n/a",H5/D5) -> 1.1147228 | L5: =F5-E5 -> 0.069902913 | M5: =COUNTIFS(P1_POA!$B$5:$B$200,A5) -> 5 | N5: =COUNTIFS(P1_POA!$B$5:$B$200,A5,P1_POA!$R$5:$R$200,"Rojo")+COUNTIFS(P1_POA!$B$5:$B$200,A5,P1_POA!$R$5:$R$200,"Amarillo") -> 4 | O5: =IF(NOT(ISNUMBER(J5)),"Gris",IF(MIN(J5,IF(ISNUMBER(K5),K5,J5))>=EVM_Verde,"Verde",IF(MIN(J5,IF(ISNUMBER(K5),K5,J5))>=EVM_Amarillo,"Amarillo","Rojo"))) -> Amarillo
A6: C2 | B6: Permanencia y graduación | C6: =SUMIFS(P1_POA!$G$5:$G$200,P1_POA!$B$5:$B$200,A6) -> 1800000 | D6: =SUMIFS(P1_POA!$J$5:$J$200,P1_POA!$B$5:$B$200,A6) -> 735300 | E6: =IF(C6=0,0,D6/C6) -> 0.4085 | F6: =IF(C6=0,0,H6/C6) -> 0.425 | G6: =IF(C6=0,0,I6/C6) -> 0.41961082 | H6: =SUMIFS(P1_POA!$L$5:$L$200,P1_POA!$B$5:$B$200,A6) -> 765000 | I6: =SUMIFS(P1_POA!$M$5:$M$200,P1_POA!$B$5:$B$200,A6) -> 755299.48 | J6: =IF(I6=0,"n/a",H6/I6) -> 1.0128433 | K6: =IF(D6=0,"n/a",H6/D6) -> 1.0403917 | L6: =F6-E6 -> 0.0165 | M6: =COUNTIFS(P1_POA!$B$5:$B$200,A6) -> 6 | N6: =COUNTIFS(P1_POA!$B$5:$B$200,A6,P1_POA!$R$5:$R$200,"Rojo")+COUNTIFS(P1_POA!$B$5:$B$200,A6,P1_POA!$R$5:$R$200,"Amarillo") -> 2 | O6: =IF(NOT(ISNUMBER(J6)),"Gris",IF(MIN(J6,IF(ISNUMBER(K6),K6,J6))>=EVM_Verde,"Verde",IF(MIN(J6,IF(ISNUMBER(K6),K6,J6))>=EVM_Amarillo,"Amarillo","Rojo"))) -> Verde
A7: C3 | B7: Vinculación laboral y trayectorias | C7: =SUMIFS(P1_POA!$G$5:$G$200,P1_POA!$B$5:$B$200,A7) -> 500000 | D7: =SUMIFS(P1_POA!$J$5:$J$200,P1_POA!$B$5:$B$200,A7) -> 268200 | E7: =IF(C7=0,0,D7/C7) -> 0.5364 | F7: =IF(C7=0,0,H7/C7) -> 0.5462 | G7: =IF(C7=0,0,I7/C7) -> 0.56501853 | H7: =SUMIFS(P1_POA!$L$5:$L$200,P1_POA!$B$5:$B$200,A7) -> 273100 | I7: =SUMIFS(P1_POA!$M$5:$M$200,P1_POA!$B$5:$B$200,A7) -> 282509.27 | J7: =IF(I7=0,"n/a",H7/I7) -> 0.96669396 | K7: =IF(D7=0,"n/a",H7/D7) -> 1.0182699 | L7: =F7-E7 -> 0.0098 | M7: =COUNTIFS(P1_POA!$B$5:$B$200,A7) -> 4 | N7: =COUNTIFS(P1_POA!$B$5:$B$200,A7,P1_POA!$R$5:$R$200,"Rojo")+COUNTIFS(P1_POA!$B$5:$B$200,A7,P1_POA!$R$5:$R$200,"Amarillo") -> 2 | O7: =IF(NOT(ISNUMBER(J7)),"Gris",IF(MIN(J7,IF(ISNUMBER(K7),K7,J7))>=EVM_Verde,"Verde",IF(MIN(J7,IF(ISNUMBER(K7),K7,J7))>=EVM_Amarillo,"Amarillo","Rojo"))) -> Verde
A8: C4 | B8: Fortalecimiento institucional | C8: =SUMIFS(P1_POA!$G$5:$G$200,P1_POA!$B$5:$B$200,A8) -> 2300000 | D8: =SUMIFS(P1_POA!$J$5:$J$200,P1_POA!$B$5:$B$200,A8) -> 722850 | E8: =IF(C8=0,0,D8/C8) -> 0.31428261 | F8: =IF(C8=0,0,H8/C8) -> 0.33804348 | G8: =IF(C8=0,0,I8/C8) -> 0.49791352 | H8: =SUMIFS(P1_POA!$L$5:$L$200,P1_POA!$B$5:$B$200,A8) -> 777500 | I8: =SUMIFS(P1_POA!$M$5:$M$200,P1_POA!$B$5:$B$200,A8) -> 1145201.1 | J8: =IF(I8=0,"n/a",H8/I8) -> 0.67892006 | K8: =IF(D8=0,"n/a",H8/D8) -> 1.0756035 | L8: =F8-E8 -> 0.02376087 | M8: =COUNTIFS(P1_POA!$B$5:$B$200,A8) -> 4 | N8: =COUNTIFS(P1_POA!$B$5:$B$200,A8,P1_POA!$R$5:$R$200,"Rojo")+COUNTIFS(P1_POA!$B$5:$B$200,A8,P1_POA!$R$5:$R$200,"Amarillo") -> 3 | O8: =IF(NOT(ISNUMBER(J8)),"Gris",IF(MIN(J8,IF(ISNUMBER(K8),K8,J8))>=EVM_Verde,"Verde",IF(MIN(J8,IF(ISNUMBER(K8),K8,J8))>=EVM_Amarillo,"Amarillo","Rojo"))) -> Rojo
A9: C5 | B9: Administración, M&E y auditoría | C9: =SUMIFS(P1_POA!$G$5:$G$200,P1_POA!$B$5:$B$200,A9) -> 870000 | D9: =SUMIFS(P1_POA!$J$5:$J$200,P1_POA!$B$5:$B$200,A9) -> 374400 | E9: =IF(C9=0,0,D9/C9) -> 0.43034483 | F9: =IF(C9=0,0,H9/C9) -> 0.45551724 | G9: =IF(C9=0,0,I9/C9) -> 0.52364863 | H9: =SUMIFS(P1_POA!$L$5:$L$200,P1_POA!$B$5:$B$200,A9) -> 396300 | I9: =SUMIFS(P1_POA!$M$5:$M$200,P1_POA!$B$5:$B$200,A9) -> 455574.31 | J9: =IF(I9=0,"n/a",H9/I9) -> 0.86989102 | K9: =IF(D9=0,"n/a",H9/D9) -> 1.0584936 | L9: =F9-E9 -> 0.025172414 | M9: =COUNTIFS(P1_POA!$B$5:$B$200,A9) -> 5 | N9: =COUNTIFS(P1_POA!$B$5:$B$200,A9,P1_POA!$R$5:$R$200,"Rojo")+COUNTIFS(P1_POA!$B$5:$B$200,A9,P1_POA!$R$5:$R$200,"Amarillo") -> 3 | O9: =IF(NOT(ISNUMBER(J9)),"Gris",IF(MIN(J9,IF(ISNUMBER(K9),K9,J9))>=EVM_Verde,"Verde",IF(MIN(J9,IF(ISNUMBER(K9),K9,J9))>=EVM_Amarillo,"Amarillo","Rojo"))) -> Amarillo
A10: TOTAL | B10: Programa | C10: =SUM(C5:C9) -> 6500000 | D10: =SUM(D5:D9) -> 2728350 | E10: =D10/C10 -> 0.41974615 | F10: =H10/C10 -> 0.44792308 | G10: =I10/C10 -> 0.52567146 | H10: =SUM(H5:H9) -> 2911500 | I10: =SUM(I5:I9) -> 3416864.5 | J10: =IF(I10=0,"n/a",H10/I10) -> 0.852097 | K10: =IF(D10=0,"n/a",H10/D10) -> 1.0671285 | L10: =F10-E10 -> 0.028176923 | M10: =SUM(M5:M9) -> 24 | N10: =SUM(N5:N9) -> 14 | O10: =IF(NOT(ISNUMBER(J10)),"Gris",IF(MIN(J10,K10)>=EVM_Verde,"Verde",IF(MIN(J10,K10)>=EVM_Amarillo,"Amarillo","Rojo"))) -> Amarillo
A12: Presupuesto POA = actividades del año 1 (reconciliado con el PEP en la hoja Controles). Umbrales en Parametros (EVM_Verde / EVM_Amarillo).

Sheet P1_Riesgos
A1: P1 · Registro y matriz de riesgos (técnicos, fiduciarios, institucionales, ambientales y sociales)
A2: DATOS SIMULADOS con fines de demostración metodológica — no son cifras reales del BID ni de la Dirección de Integración.
A3: Puntaje = probabilidad × impacto (escala 1-5). Las columnas S-T son auxiliares para el ranking del informe mensual.
A4: ID | B4: Categoría | C4: Riesgo | D4: Causa / disparador | E4: Prob. (1-5) | F4: Impacto (1-5) | G4: Puntaje | H4: Nivel | I4: Respuesta | J4: Acción de mitigación | K4: Responsable | L4: Fecha límite | M4: Estado | N4: Prob. residual | O4: Impacto residual | P4: Puntaje residual | Q4: Nivel residual | R4: Días a la fecha límite | S4: Aux. puntaje | T4: Ranking
A5: R-01 | B5: Institucional | C5: Rotación o vacantes del personal clave de la UGP | D5: Contratos anuales y alta demanda de perfiles | E5: 3 | F5: 4 | G5: =E5*F5 -> 12 | H5: =IF(G5>=Riesgo_Alto,"Alto",IF(G5>=Riesgo_Medio,"Medio","Bajo")) -> Medio | I5: Mitigar | J5: Plan de sucesión, manual de funciones y prórrogas anticipadas | K5: Coordinador General | L5: 46660 | M5: En mitigación | N5: 2 | O5: 3 | P5: =N5*O5 -> 6 | Q5: =IF(P5>=Riesgo_Alto,"Alto",IF(P5>=Riesgo_Medio,"Medio","Bajo")) -> Bajo | R5: =IF(M5="Cerrado","",L5-Fecha_Corte) -> 92 | S5: =IF(M5="Cerrado",0,G5+(1000-ROW())/100000) -> 12.00995 | T5: =RANK(S5,$S$5:$S$200) -> 4
A6: R-02 | B6: Fiduciario | C6: Retrasos en adquisiciones por observaciones en las No Objeciones | D6: Expedientes incompletos o términos de referencia ambiguos | E6: 4 | F6: 4 | G6: =E6*F6 -> 16 | H6: =IF(G6>=Riesgo_Alto,"Alto",IF(G6>=Riesgo_Medio,"Medio","Bajo")) -> Alto | I6: Mitigar | J6: Listas de verificación previas al envío, plantillas estándar y calendario de No Objeciones | K6: Esp. Adquisiciones | L6: 46599 | M6: En mitigación | N6: 3 | O6: 3 | P6: =N6*O6 -> 9 | Q6: =IF(P6>=Riesgo_Alto,"Alto",IF(P6>=Riesgo_Medio,"Medio","Bajo")) -> Medio | R6: =IF(M6="Cerrado","",L6-Fecha_Corte) -> 31 | S6: =IF(M6="Cerrado",0,G6+(1000-ROW())/100000) -> 16.00994 | T6: =RANK(S6,$S$5:$S$200) -> 1
A7: R-03 | B7: Fiduciario | C7: Ejecución presupuestaria por debajo del PEP | D7: Retrasos físicos y de contratación | E7: 4 | F7: 4 | G7: =E7*F7 -> 16 | H7: =IF(G7>=Riesgo_Alto,"Alto",IF(G7>=Riesgo_Medio,"Medio","Bajo")) -> Alto | I7: Mitigar | J7: Seguimiento mensual SPI/CPI y reprogramación trimestral con alertas tempranas | K7: Coordinador General | L7: 46660 | M7: Abierto | N7: 3 | O7: 3 | P7: =N7*O7 -> 9 | Q7: =IF(P7>=Riesgo_Alto,"Alto",IF(P7>=Riesgo_Medio,"Medio","Bajo")) -> Medio | R7: =IF(M7="Cerrado","",L7-Fecha_Corte) -> 92 | S7: =IF(M7="Cerrado",0,G7+(1000-ROW())/100000) -> 16.00993 | T7: =RANK(S7,$S$5:$S$200) -> 2
A8: R-04 | B8: Fiduciario | C8: Justificación tardía de anticipos retrasa nuevos desembolsos | D8: Rendiciones atrasadas y soporte incompleto | E8: 3 | F8: 4 | G8: =E8*F8 -> 12 | H8: =IF(G8>=Riesgo_Alto,"Alto",IF(G8>=Riesgo_Medio,"Medio","Bajo")) -> Medio | I8: Mitigar | J8: Justificación quincenal y control del umbral del 80 % de anticipos | K8: Esp. Financiero | L8: 46583 | M8: En mitigación | N8: 2 | O8: 3 | P8: =N8*O8 -> 6 | Q8: =IF(P8>=Riesgo_Alto,"Alto",IF(P8>=Riesgo_Medio,"Medio","Bajo")) -> Bajo | R8: =IF(M8="Cerrado","",L8-Fecha_Corte) -> 15 | S8: =IF(M8="Cerrado",0,G8+(1000-ROW())/100000) -> 12.00992 | T8: =RANK(S8,$S$5:$S$200) -> 5
A9: R-05 | B9: Técnico | C9: Bajo alcance en departamentos de prioridad alta | D9: Barreras de acceso, difusión insuficiente en zonas rurales | E9: 3 | F9: 4 | G9: =E9*F9 -> 12 | H9: =IF(G9>=Riesgo_Alto,"Alto",IF(G9>=Riesgo_Medio,"Medio","Bajo")) -> Medio | I9: Mitigar | J9: Focalización por índice, ferias departamentales y alianzas locales | K9: Esp. Social | L9: 46691 | M9: Abierto | N9: 2 | O9: 3 | P9: =N9*O9 -> 6 | Q9: =IF(P9>=Riesgo_Alto,"Alto",IF(P9>=Riesgo_Medio,"Medio","Bajo")) -> Bajo | R9: =IF(M9="Cerrado","",L9-Fecha_Corte) -> 123 | S9: =IF(M9="Cerrado",0,G9+(1000-ROW())/100000) -> 12.00991 | T9: =RANK(S9,$S$5:$S$200) -> 6
A10: R-06 | B10: Técnico | C10: Retraso en el desarrollo del sistema de información de trayectorias | D10: Requisitos cambiantes e integración con instituciones | E10: 4 | F10: 3 | G10: =E10*F10 -> 12 | H10: =IF(G10>=Riesgo_Alto,"Alto",IF(G10>=Riesgo_Medio,"Medio","Bajo")) -> Medio | I10: Mitigar | J10: Entregas por módulos, pruebas tempranas y gobierno de requisitos | K10: Esp. Planificación, M&S | L10: 46630 | M10: En mitigación | N10: 3 | O10: 3 | P10: =N10*O10 -> 9 | Q10: =IF(P10>=Riesgo_Alto,"Alto",IF(P10>=Riesgo_Medio,"Medio","Bajo")) -> Medio | R10: =IF(M10="Cerrado","",L10-Fecha_Corte) -> 62 | S10: =IF(M10="Cerrado",0,G10+(1000-ROW())/100000) -> 12.0099 | T10: =RANK(S10,$S$5:$S$200) -> 7
A11: R-07 | B11: Institucional | C11: Débil articulación con instituciones de educación postsecundaria | D11: Capacidades y prioridades distintas | E11: 3 | F11: 3 | G11: =E11*F11 -> 9 | H11: =IF(G11>=Riesgo_Alto,"Alto",IF(G11>=Riesgo_Medio,"Medio","Bajo")) -> Medio | I11: Mitigar | J11: Convenios con compromisos medibles y mesa de coordinación | K11: Coordinador General | L11: 46660 | M11: Abierto | N11: 2 | O11: 3 | P11: =N11*O11 -> 6 | Q11: =IF(P11>=Riesgo_Alto,"Alto",IF(P11>=Riesgo_Medio,"Medio","Bajo")) -> Bajo | R11: =IF(M11="Cerrado","",L11-Fecha_Corte) -> 92 | S11: =IF(M11="Cerrado",0,G11+(1000-ROW())/100000) -> 9.00989 | T11: =RANK(S11,$S$5:$S$200) -> 11
A12: R-08 | B12: Ambiental y social | C12: Exclusión de grupos prioritarios (discapacidad, madres jóvenes, retornados) | D12: Barreras de accesibilidad y de información | E12: 3 | F12: 5 | G12: =E12*F12 -> 15 | H12: =IF(G12>=Riesgo_Alto,"Alto",IF(G12>=Riesgo_Medio,"Medio","Bajo")) -> Alto | I12: Mitigar | J12: Ajustes razonables, metas por grupo y monitoreo de cobertura | K12: Esp. Social | L12: 46630 | M12: En mitigación | N12: 2 | O12: 4 | P12: =N12*O12 -> 8 | Q12: =IF(P12>=Riesgo_Alto,"Alto",IF(P12>=Riesgo_Medio,"Medio","Bajo")) -> Medio | R12: =IF(M12="Cerrado","",L12-Fecha_Corte) -> 62 | S12: =IF(M12="Cerrado",0,G12+(1000-ROW())/100000) -> 15.00988 | T12: =RANK(S12,$S$5:$S$200) -> 3
A13: R-09 | B13: Ambiental y social | C13: Incidente de protección de datos personales de beneficiarios | D13: Manejo de información sensible en varias entidades | E13: 2 | F13: 5 | G13: =E13*F13 -> 10 | H13: =IF(G13>=Riesgo_Alto,"Alto",IF(G13>=Riesgo_Medio,"Medio","Bajo")) -> Medio | I13: Mitigar | J13: Protocolo de datos, accesos por rol y capacitación | K13: Esp. Social | L13: 46599 | M13: En mitigación | N13: 1 | O13: 5 | P13: =N13*O13 -> 5 | Q13: =IF(P13>=Riesgo_Alto,"Alto",IF(P13>=Riesgo_Medio,"Medio","Bajo")) -> Bajo | R13: =IF(M13="Cerrado","",L13-Fecha_Corte) -> 31 | S13: =IF(M13="Cerrado",0,G13+(1000-ROW())/100000) -> 10.00987 | T13: =RANK(S13,$S$5:$S$200) -> 10
A14: R-10 | B14: Cumplimiento | C14: Incumplimiento de plazos de informes al BID | D14: Cierres contables y de indicadores desfasados | E14: 2 | F14: 4 | G14: =E14*F14 -> 8 | H14: =IF(G14>=Riesgo_Alto,"Alto",IF(G14>=Riesgo_Medio,"Medio","Bajo")) -> Medio | I14: Mitigar | J14: Calendario de reportes con alertas a 30 días | K14: Esp. Planificación, M&S | L14: 46599 | M14: En mitigación | N14: 1 | O14: 4 | P14: =N14*O14 -> 4 | Q14: =IF(P14>=Riesgo_Alto,"Alto",IF(P14>=Riesgo_Medio,"Medio","Bajo")) -> Bajo | R14: =IF(M14="Cerrado","",L14-Fecha_Corte) -> 31 | S14: =IF(M14="Cerrado",0,G14+(1000-ROW())/100000) -> 8.00986 | T14: =RANK(S14,$S$5:$S$200) -> 13
A15: R-11 | B15: Cumplimiento | C15: Modificar el MOP o reasignar fondos sin No Objeción previa | D15: Cambios operativos urgentes | E15: 1 | F15: 4 | G15: =E15*F15 -> 4 | H15: =IF(G15>=Riesgo_Alto,"Alto",IF(G15>=Riesgo_Medio,"Medio","Bajo")) -> Bajo | I15: Evitar | J15: Regla: ningún cambio sin No Objeción; registro de cambios (CCB) | K15: Coordinador General | L15: 46752 | M15: Abierto | N15: 1 | O15: 4 | P15: =N15*O15 -> 4 | Q15: =IF(P15>=Riesgo_Alto,"Alto",IF(P15>=Riesgo_Medio,"Medio","Bajo")) -> Bajo | R15: =IF(M15="Cerrado","",L15-Fecha_Corte) -> 184 | S15: =IF(M15="Cerrado",0,G15+(1000-ROW())/100000) -> 4.00985 | T15: =RANK(S15,$S$5:$S$200) -> 15
